I0314 02:41:22.046087 151178 init.cc:233] ENV [CUSTOM_DEVICE_ROOT]=/root/miniconda3/envs/paddle_env_py310/lib/python3.10/site-packages/paddle_custom_device
I0314 02:41:22.046387 151178 init.cc:142] Try loading custom device libs from: [/root/miniconda3/envs/paddle_env_py310/lib/python3.10/site-packages/paddle_custom_device]
sdaa plugin compiled with gcc
PaddlePaddle Compilation Commit: e5b01458d31bab831dbd96a53522bf207b2fcd9e
PaddlePaddle Compilation Version: 2.6.0
+---------+--------+---------------+--------------+-------------+----------+-----------+-----------+-------------+-------+---------------------+--------------------+
|         | paddle | paddle_commit | sdaa_runtime | sdaa_driver | teco_dnn | teco_blas | teco_tccl | teco_custom | sdpti | paddle_sdaa_version | paddle_sdaa_commit |
+---------+--------+---------------+--------------+-------------+----------+-----------+-----------+-------------+-------+---------------------+--------------------+
| Version | 2.6.0  | e5b0145       | 2.0.0        | 2.0.0       | 2.0.0    | 2.0.0     | 1.21.0    | 1.22.0      | 1.3.1 | 2.0.0               | 38be61b            |
+---------+--------+---------------+--------------+-------------+----------+-----------+-----------+-------------+-------+---------------------+--------------------+
+--------------------------+---------------+---------------+
| Variable Name            | Default Value | Current Value |
+--------------------------+---------------+---------------+
| CUSTOM_DEVICE_BLACK_LIST |               |               |
+--------------------------+---------------+---------------+
| ENABLE_SDPTI             | 1             | 1             |
+--------------------------+---------------+---------------+
| HIGH_PERFORMANCE_CONV    | 0             | 0             |
+--------------------------+---------------+---------------+
| HIGH_PERFORMANCE_GEMM    | 0             | 0             |
+--------------------------+---------------+---------------+
| RANDOM_ALIGN_NV_DEVICE   |               |               |
+--------------------------+---------------+---------------+
| PADDLE_XCCL_BACKEND      |               | sdaa          |
+--------------------------+---------------+---------------+
| HIGH_PRECISION_OP_LIST   |               |               |
+--------------------------+---------------+---------------+
| FLAGS_sdaa_reuse_event   | true          | true          |
+--------------------------+---------------+---------------+
| FLAGS_sdaa_runtime_debug | false         | false         |
+--------------------------+---------------+---------------+
| FLAGS_sdaa_matmul_scale  | 1.0           | 1.0           |
+--------------------------+---------------+---------------+
| DUMP_INTO_PROFILER       | 0             | 0             |
+--------------------------+---------------+---------------+
I0314 02:41:22.114176 151178 custom_device.cc:1109] Successed in loading custom runtime in lib: /root/miniconda3/envs/paddle_env_py310/lib/python3.10/site-packages/paddle_custom_device/libpaddle-sdaa.so
I0314 02:41:22.116348 151178 custom_kernel.cc:63] Successed in loading 271 custom kernel(s) from loaded lib(s), will be used like native ones.
I0314 02:41:22.116439 151178 init.cc:154] Finished in LoadCustomDevice with libs_path: [/root/miniconda3/envs/paddle_env_py310/lib/python3.10/site-packages/paddle_custom_device]
I0314 02:41:22.116454 151178 init.cc:239] CustomDevice: sdaa, visible devices count: 1
Warning: Unable to use numba in PP-Tracking, please install numba, for example(python3.7): `pip install numba==0.56.4`
[2025-03-14 02:41:23,128] [   DEBUG] __init__.py:342 - matplotlib data path: /root/miniconda3/envs/paddle_env_py310/lib/python3.10/site-packages/matplotlib/mpl-data
[2025-03-14 02:41:23,135] [   DEBUG] __init__.py:342 - CONFIGDIR=/root/.config/matplotlib
[2025-03-14 02:41:23,137] [   DEBUG] __init__.py:1557 - interactive is False
[2025-03-14 02:41:23,137] [   DEBUG] __init__.py:1558 - platform is linux
[2025-03-14 02:41:23,280] [   DEBUG] __init__.py:342 - CACHEDIR=/root/.cache/matplotlib
[2025-03-14 02:41:23,282] [   DEBUG] font_manager.py:1635 - Using fontManager instance from /root/.cache/matplotlib/fontlist-v390.json
Warning: Unable to use numba in PP-Tracking, please install numba, for example(python3.7): `pip install numba==0.56.4`
Warning: import ppdet from source directory without installing, run 'python setup.py install' to install ppdet firstly
I0314 02:41:23.998232 151178 tcp_utils.cc:130] Successfully connected to 192.166.0.6:63440
Config dataset_dir dataset/mot/MOT17 is not exits, dataset config is not valid
Traceback (most recent call last):
  File "/data/whb/oc_sort/PaddleDetection/tools/train.py", line 215, in <module>
    main()
  File "/data/whb/oc_sort/PaddleDetection/tools/train.py", line 211, in main
    run(FLAGS, cfg)
  File "/data/whb/oc_sort/PaddleDetection/tools/train.py", line 150, in run
    trainer = Trainer(cfg, mode='train')
  File "/data/whb/oc_sort/PaddleDetection/ppdet/engine/trainer.py", line 123, in __init__
    self.loader = create('{}Reader'.format(capital_mode))(
  File "/data/whb/oc_sort/PaddleDetection/ppdet/data/reader.py", line 189, in __call__
    self.dataset.check_or_download_dataset()
  File "/data/whb/oc_sort/PaddleDetection/ppdet/data/source/dataset.py", line 116, in check_or_download_dataset
    self.dataset_dir = get_dataset_path(self.dataset_dir, self.anno_path,
  File "/data/whb/oc_sort/PaddleDetection/ppdet/utils/download.py", line 191, in get_dataset_path
    raise ValueError(
ValueError: Dataset /data/whb/oc_sort/PaddleDetection/dataset/mot/MOT17 is not valid for reason above, please check again.
I0314 02:42:50.247248 151412 init.cc:233] ENV [CUSTOM_DEVICE_ROOT]=/root/miniconda3/envs/paddle_env_py310/lib/python3.10/site-packages/paddle_custom_device
I0314 02:42:50.247291 151412 init.cc:142] Try loading custom device libs from: [/root/miniconda3/envs/paddle_env_py310/lib/python3.10/site-packages/paddle_custom_device]
sdaa plugin compiled with gcc
PaddlePaddle Compilation Commit: e5b01458d31bab831dbd96a53522bf207b2fcd9e
PaddlePaddle Compilation Version: 2.6.0
+---------+--------+---------------+--------------+-------------+----------+-----------+-----------+-------------+-------+---------------------+--------------------+
|         | paddle | paddle_commit | sdaa_runtime | sdaa_driver | teco_dnn | teco_blas | teco_tccl | teco_custom | sdpti | paddle_sdaa_version | paddle_sdaa_commit |
+---------+--------+---------------+--------------+-------------+----------+-----------+-----------+-------------+-------+---------------------+--------------------+
| Version | 2.6.0  | e5b0145       | 2.0.0        | 2.0.0       | 2.0.0    | 2.0.0     | 1.21.0    | 1.22.0      | 1.3.1 | 2.0.0               | 38be61b            |
+---------+--------+---------------+--------------+-------------+----------+-----------+-----------+-------------+-------+---------------------+--------------------+
+--------------------------+---------------+---------------+
| Variable Name            | Default Value | Current Value |
+--------------------------+---------------+---------------+
| CUSTOM_DEVICE_BLACK_LIST |               |               |
+--------------------------+---------------+---------------+
| ENABLE_SDPTI             | 1             | 1             |
+--------------------------+---------------+---------------+
| HIGH_PERFORMANCE_CONV    | 0             | 0             |
+--------------------------+---------------+---------------+
| HIGH_PERFORMANCE_GEMM    | 0             | 0             |
+--------------------------+---------------+---------------+
| RANDOM_ALIGN_NV_DEVICE   |               |               |
+--------------------------+---------------+---------------+
| PADDLE_XCCL_BACKEND      |               | sdaa          |
+--------------------------+---------------+---------------+
| HIGH_PRECISION_OP_LIST   |               |               |
+--------------------------+---------------+---------------+
| FLAGS_sdaa_reuse_event   | true          | true          |
+--------------------------+---------------+---------------+
| FLAGS_sdaa_runtime_debug | false         | false         |
+--------------------------+---------------+---------------+
| FLAGS_sdaa_matmul_scale  | 1.0           | 1.0           |
+--------------------------+---------------+---------------+
| DUMP_INTO_PROFILER       | 0             | 0             |
+--------------------------+---------------+---------------+
I0314 02:42:50.345866 151412 custom_device.cc:1109] Successed in loading custom runtime in lib: /root/miniconda3/envs/paddle_env_py310/lib/python3.10/site-packages/paddle_custom_device/libpaddle-sdaa.so
I0314 02:42:50.348520 151412 custom_kernel.cc:63] Successed in loading 271 custom kernel(s) from loaded lib(s), will be used like native ones.
I0314 02:42:50.348623 151412 init.cc:154] Finished in LoadCustomDevice with libs_path: [/root/miniconda3/envs/paddle_env_py310/lib/python3.10/site-packages/paddle_custom_device]
I0314 02:42:50.348641 151412 init.cc:239] CustomDevice: sdaa, visible devices count: 1
Warning: Unable to use numba in PP-Tracking, please install numba, for example(python3.7): `pip install numba==0.56.4`
[2025-03-14 02:42:51,534] [   DEBUG] __init__.py:342 - matplotlib data path: /root/miniconda3/envs/paddle_env_py310/lib/python3.10/site-packages/matplotlib/mpl-data
[2025-03-14 02:42:51,542] [   DEBUG] __init__.py:342 - CONFIGDIR=/root/.config/matplotlib
[2025-03-14 02:42:51,543] [   DEBUG] __init__.py:1557 - interactive is False
[2025-03-14 02:42:51,544] [   DEBUG] __init__.py:1558 - platform is linux
[2025-03-14 02:42:51,671] [   DEBUG] __init__.py:342 - CACHEDIR=/root/.cache/matplotlib
[2025-03-14 02:42:51,672] [   DEBUG] font_manager.py:1635 - Using fontManager instance from /root/.cache/matplotlib/fontlist-v390.json
Warning: Unable to use numba in PP-Tracking, please install numba, for example(python3.7): `pip install numba==0.56.4`
I0314 02:42:52.362640 151412 tcp_utils.cc:130] Successfully connected to 192.166.0.6:61634
Config dataset_dir dataset/mot/MOT17 is not exits, dataset config is not valid
Traceback (most recent call last):
  File "/data/whb/oc_sort/PaddleDetection/tools/train.py", line 215, in <module>
    main()
  File "/data/whb/oc_sort/PaddleDetection/tools/train.py", line 211, in main
    run(FLAGS, cfg)
  File "/data/whb/oc_sort/PaddleDetection/tools/train.py", line 150, in run
    trainer = Trainer(cfg, mode='train')
  File "/data/whb/oc_sort/PaddleDetection/ppdet/engine/trainer.py", line 123, in __init__
    self.loader = create('{}Reader'.format(capital_mode))(
  File "/data/whb/oc_sort/PaddleDetection/ppdet/data/reader.py", line 189, in __call__
    self.dataset.check_or_download_dataset()
  File "/data/whb/oc_sort/PaddleDetection/ppdet/data/source/dataset.py", line 116, in check_or_download_dataset
    self.dataset_dir = get_dataset_path(self.dataset_dir, self.anno_path,
  File "/data/whb/oc_sort/PaddleDetection/ppdet/utils/download.py", line 191, in get_dataset_path
    raise ValueError(
ValueError: Dataset /data/whb/oc_sort/PaddleDetection/dataset/mot/MOT17 is not valid for reason above, please check again.
I0314 02:44:33.027702 151618 init.cc:233] ENV [CUSTOM_DEVICE_ROOT]=/root/miniconda3/envs/paddle_env_py310/lib/python3.10/site-packages/paddle_custom_device
I0314 02:44:33.027740 151618 init.cc:142] Try loading custom device libs from: [/root/miniconda3/envs/paddle_env_py310/lib/python3.10/site-packages/paddle_custom_device]
sdaa plugin compiled with gcc
PaddlePaddle Compilation Commit: e5b01458d31bab831dbd96a53522bf207b2fcd9e
PaddlePaddle Compilation Version: 2.6.0
+---------+--------+---------------+--------------+-------------+----------+-----------+-----------+-------------+-------+---------------------+--------------------+
|         | paddle | paddle_commit | sdaa_runtime | sdaa_driver | teco_dnn | teco_blas | teco_tccl | teco_custom | sdpti | paddle_sdaa_version | paddle_sdaa_commit |
+---------+--------+---------------+--------------+-------------+----------+-----------+-----------+-------------+-------+---------------------+--------------------+
| Version | 2.6.0  | e5b0145       | 2.0.0        | 2.0.0       | 2.0.0    | 2.0.0     | 1.21.0    | 1.22.0      | 1.3.1 | 2.0.0               | 38be61b            |
+---------+--------+---------------+--------------+-------------+----------+-----------+-----------+-------------+-------+---------------------+--------------------+
+--------------------------+---------------+---------------+
| Variable Name            | Default Value | Current Value |
+--------------------------+---------------+---------------+
| CUSTOM_DEVICE_BLACK_LIST |               |               |
+--------------------------+---------------+---------------+
| ENABLE_SDPTI             | 1             | 1             |
+--------------------------+---------------+---------------+
| HIGH_PERFORMANCE_CONV    | 0             | 0             |
+--------------------------+---------------+---------------+
| HIGH_PERFORMANCE_GEMM    | 0             | 0             |
+--------------------------+---------------+---------------+
| RANDOM_ALIGN_NV_DEVICE   |               |               |
+--------------------------+---------------+---------------+
| PADDLE_XCCL_BACKEND      |               | sdaa          |
+--------------------------+---------------+---------------+
| HIGH_PRECISION_OP_LIST   |               |               |
+--------------------------+---------------+---------------+
| FLAGS_sdaa_reuse_event   | true          | true          |
+--------------------------+---------------+---------------+
| FLAGS_sdaa_runtime_debug | false         | false         |
+--------------------------+---------------+---------------+
| FLAGS_sdaa_matmul_scale  | 1.0           | 1.0           |
+--------------------------+---------------+---------------+
| DUMP_INTO_PROFILER       | 0             | 0             |
+--------------------------+---------------+---------------+
I0314 02:44:33.129194 151618 custom_device.cc:1109] Successed in loading custom runtime in lib: /root/miniconda3/envs/paddle_env_py310/lib/python3.10/site-packages/paddle_custom_device/libpaddle-sdaa.so
I0314 02:44:33.132018 151618 custom_kernel.cc:63] Successed in loading 271 custom kernel(s) from loaded lib(s), will be used like native ones.
I0314 02:44:33.132119 151618 init.cc:154] Finished in LoadCustomDevice with libs_path: [/root/miniconda3/envs/paddle_env_py310/lib/python3.10/site-packages/paddle_custom_device]
I0314 02:44:33.132143 151618 init.cc:239] CustomDevice: sdaa, visible devices count: 1
Warning: Unable to use numba in PP-Tracking, please install numba, for example(python3.7): `pip install numba==0.56.4`
[2025-03-14 02:44:34,286] [   DEBUG] __init__.py:342 - matplotlib data path: /root/miniconda3/envs/paddle_env_py310/lib/python3.10/site-packages/matplotlib/mpl-data
[2025-03-14 02:44:34,293] [   DEBUG] __init__.py:342 - CONFIGDIR=/root/.config/matplotlib
[2025-03-14 02:44:34,295] [   DEBUG] __init__.py:1557 - interactive is False
[2025-03-14 02:44:34,295] [   DEBUG] __init__.py:1558 - platform is linux
[2025-03-14 02:44:34,428] [   DEBUG] __init__.py:342 - CACHEDIR=/root/.cache/matplotlib
[2025-03-14 02:44:34,429] [   DEBUG] font_manager.py:1635 - Using fontManager instance from /root/.cache/matplotlib/fontlist-v390.json
Warning: Unable to use numba in PP-Tracking, please install numba, for example(python3.7): `pip install numba==0.56.4`
I0314 02:44:34.952289 151618 tcp_utils.cc:107] Retry to connect to 192.166.0.6:40012 while the server is not yet listening.


--------------------------------------
C++ Traceback (most recent call last):
--------------------------------------
0   phi::distributed::CreateOrGetGlobalTCPStore()
1   phi::distributed::TCPStore::TCPStore(std::string, unsigned short, bool, unsigned long, int)
2   phi::distributed::detail::TCPClient::connect(std::string, unsigned short)
3   phi::distributed::tcputils::tcp_connect(std::string, std::string, int, std::chrono::duration<long, std::ratio<1l, 1l> >)

----------------------
Error Message Summary:
----------------------
FatalError: `Termination signal` is detected by the operating system.
  [TimeInfo: *** Aborted at 1741920276 (unix time) try "date -d @1741920276" if you are using GNU date ***]
  [SignalInfo: *** SIGTERM (@0x24fee) received by PID 151618 (TID 0x7efec4ea8740) from PID 151534 ***]

I0314 02:50:15.308275 152088 init.cc:233] ENV [CUSTOM_DEVICE_ROOT]=/root/miniconda3/envs/paddle_env_py310/lib/python3.10/site-packages/paddle_custom_device
I0314 02:50:15.308319 152088 init.cc:142] Try loading custom device libs from: [/root/miniconda3/envs/paddle_env_py310/lib/python3.10/site-packages/paddle_custom_device]
sdaa plugin compiled with gcc
PaddlePaddle Compilation Commit: e5b01458d31bab831dbd96a53522bf207b2fcd9e
PaddlePaddle Compilation Version: 2.6.0
+---------+--------+---------------+--------------+-------------+----------+-----------+-----------+-------------+-------+---------------------+--------------------+
|         | paddle | paddle_commit | sdaa_runtime | sdaa_driver | teco_dnn | teco_blas | teco_tccl | teco_custom | sdpti | paddle_sdaa_version | paddle_sdaa_commit |
+---------+--------+---------------+--------------+-------------+----------+-----------+-----------+-------------+-------+---------------------+--------------------+
| Version | 2.6.0  | e5b0145       | 2.0.0        | 2.0.0       | 2.0.0    | 2.0.0     | 1.21.0    | 1.22.0      | 1.3.1 | 2.0.0               | 38be61b            |
+---------+--------+---------------+--------------+-------------+----------+-----------+-----------+-------------+-------+---------------------+--------------------+
+--------------------------+---------------+---------------+
| Variable Name            | Default Value | Current Value |
+--------------------------+---------------+---------------+
| CUSTOM_DEVICE_BLACK_LIST |               |               |
+--------------------------+---------------+---------------+
| ENABLE_SDPTI             | 1             | 1             |
+--------------------------+---------------+---------------+
| HIGH_PERFORMANCE_CONV    | 0             | 0             |
+--------------------------+---------------+---------------+
| HIGH_PERFORMANCE_GEMM    | 0             | 0             |
+--------------------------+---------------+---------------+
| RANDOM_ALIGN_NV_DEVICE   |               |               |
+--------------------------+---------------+---------------+
| PADDLE_XCCL_BACKEND      |               | sdaa          |
+--------------------------+---------------+---------------+
| HIGH_PRECISION_OP_LIST   |               |               |
+--------------------------+---------------+---------------+
| FLAGS_sdaa_reuse_event   | true          | true          |
+--------------------------+---------------+---------------+
| FLAGS_sdaa_runtime_debug | false         | false         |
+--------------------------+---------------+---------------+
| FLAGS_sdaa_matmul_scale  | 1.0           | 1.0           |
+--------------------------+---------------+---------------+
| DUMP_INTO_PROFILER       | 0             | 0             |
+--------------------------+---------------+---------------+
I0314 02:50:15.406960 152088 custom_device.cc:1109] Successed in loading custom runtime in lib: /root/miniconda3/envs/paddle_env_py310/lib/python3.10/site-packages/paddle_custom_device/libpaddle-sdaa.so
I0314 02:50:15.409734 152088 custom_kernel.cc:63] Successed in loading 271 custom kernel(s) from loaded lib(s), will be used like native ones.
I0314 02:50:15.409840 152088 init.cc:154] Finished in LoadCustomDevice with libs_path: [/root/miniconda3/envs/paddle_env_py310/lib/python3.10/site-packages/paddle_custom_device]
I0314 02:50:15.409857 152088 init.cc:239] CustomDevice: sdaa, visible devices count: 1
Warning: Unable to use numba in PP-Tracking, please install numba, for example(python3.7): `pip install numba==0.56.4`
[2025-03-14 02:50:16,549] [   DEBUG] __init__.py:342 - matplotlib data path: /root/miniconda3/envs/paddle_env_py310/lib/python3.10/site-packages/matplotlib/mpl-data
[2025-03-14 02:50:16,556] [   DEBUG] __init__.py:342 - CONFIGDIR=/root/.config/matplotlib
[2025-03-14 02:50:16,558] [   DEBUG] __init__.py:1557 - interactive is False
[2025-03-14 02:50:16,558] [   DEBUG] __init__.py:1558 - platform is linux
[2025-03-14 02:50:16,690] [   DEBUG] __init__.py:342 - CACHEDIR=/root/.cache/matplotlib
[2025-03-14 02:50:16,691] [   DEBUG] font_manager.py:1635 - Using fontManager instance from /root/.cache/matplotlib/fontlist-v390.json
Warning: Unable to use numba in PP-Tracking, please install numba, for example(python3.7): `pip install numba==0.56.4`
I0314 02:50:17.407028 152088 tcp_utils.cc:107] Retry to connect to 192.166.0.6:38407 while the server is not yet listening.
I0314 02:50:20.407392 152088 tcp_utils.cc:130] Successfully connected to 192.166.0.6:38407
loading annotations into memory...
Done (t=0.27s)
creating index...
index created!
Exception in thread Thread-1 (_thread_loop):
Traceback (most recent call last):
  File "/root/miniconda3/envs/paddle_env_py310/lib/python3.10/site-packages/paddle/io/dataloader/dataloader_iter.py", line 692, in _get_data
    data = self._data_queue.get(timeout=self._timeout)
  File "/root/miniconda3/envs/paddle_env_py310/lib/python3.10/multiprocessing/queues.py", line 114, in get
    raise Empty
_queue.Empty

During handling of the above exception, another exception occurred:

Traceback (most recent call last):
  File "/root/miniconda3/envs/paddle_env_py310/lib/python3.10/threading.py", line 1016, in _bootstrap_inner
    self.run()
  File "/root/miniconda3/envs/paddle_env_py310/lib/python3.10/threading.py", line 953, in run
    self._target(*self._args, **self._kwargs)
  File "/root/miniconda3/envs/paddle_env_py310/lib/python3.10/site-packages/paddle/io/dataloader/dataloader_iter.py", line 603, in _thread_loop
    batch = self._get_data()
  File "/root/miniconda3/envs/paddle_env_py310/lib/python3.10/site-packages/paddle/io/dataloader/dataloader_iter.py", line 707, in _get_data
    raise RuntimeError(
RuntimeError: DataLoader 4 workers exit unexpectedly, pids: 152198, 152203, 152205, 152207
